[2025-04-20T20:43:10.181+0000] {local_task_job_runner.py:120} INFO - ::group::Pre task execution logs
[2025-04-20T20:43:10.232+0000] {taskinstance.py:2076} INFO - Dependencies all met for dep_context=non-requeueable deps ti=<TaskInstance: log_etl_dag.ingest_logs_to_minio scheduled__2025-04-19T00:00:00+00:00 [queued]>
[2025-04-20T20:43:10.250+0000] {taskinstance.py:2076} INFO - Dependencies all met for dep_context=requeueable deps ti=<TaskInstance: log_etl_dag.ingest_logs_to_minio scheduled__2025-04-19T00:00:00+00:00 [queued]>
[2025-04-20T20:43:10.252+0000] {taskinstance.py:2306} INFO - Starting attempt 2 of 2
[2025-04-20T20:43:10.280+0000] {taskinstance.py:2330} INFO - Executing <Task(BashOperator): ingest_logs_to_minio> on 2025-04-19 00:00:00+00:00
[2025-04-20T20:43:10.298+0000] {logging_mixin.py:188} WARNING - /home/***/.local/lib/python3.12/site-packages/***/task/task_runner/standard_task_runner.py:61 DeprecationWarning: This process (pid=204) is multi-threaded, use of fork() may lead to deadlocks in the child.
[2025-04-20T20:43:10.301+0000] {standard_task_runner.py:63} INFO - Started process 218 to run task
[2025-04-20T20:43:10.294+0000] {standard_task_runner.py:90} INFO - Running: ['***', 'tasks', 'run', 'log_etl_dag', 'ingest_logs_to_minio', 'scheduled__2025-04-19T00:00:00+00:00', '--job-id', '47', '--raw', '--subdir', 'DAGS_FOLDER/log_etl_dag.py', '--cfg-path', '/tmp/tmp5a2ky1bc']
[2025-04-20T20:43:10.303+0000] {standard_task_runner.py:91} INFO - Job 47: Subtask ingest_logs_to_minio
[2025-04-20T20:43:10.325+0000] {logging_mixin.py:188} WARNING - /home/***/.local/lib/python3.12/site-packages/***/settings.py:195 DeprecationWarning: The sql_alchemy_conn option in [core] has been moved to the sql_alchemy_conn option in [database] - the old setting has been used, but please update your config.
[2025-04-20T20:43:10.370+0000] {task_command.py:426} INFO - Running <TaskInstance: log_etl_dag.ingest_logs_to_minio scheduled__2025-04-19T00:00:00+00:00 [running]> on host 171610a68e17
[2025-04-20T20:43:10.497+0000] {taskinstance.py:2648} INFO - Exporting env vars: AIRFLOW_CTX_DAG_OWNER='***' AIRFLOW_CTX_DAG_ID='log_etl_dag' AIRFLOW_CTX_TASK_ID='ingest_logs_to_minio' AIRFLOW_CTX_EXECUTION_DATE='2025-04-19T00:00:00+00:00' AIRFLOW_CTX_TRY_NUMBER='2' AIRFLOW_CTX_DAG_RUN_ID='scheduled__2025-04-19T00:00:00+00:00'
[2025-04-20T20:43:10.500+0000] {taskinstance.py:430} INFO - ::endgroup::
[2025-04-20T20:43:10.546+0000] {subprocess.py:63} INFO - Tmp dir root location: /tmp
[2025-04-20T20:43:10.547+0000] {subprocess.py:75} INFO - Running command: ['/usr/bin/bash', '-c', '\n        apt update && apt install -y mc &&         mc alias set localminio http://minio:9000 minioadmin minioadmin &&         mc cp /opt/***/data/access_log.txt localminio/log-bucket/raw-logs/\n        ']
[2025-04-20T20:43:10.562+0000] {subprocess.py:86} INFO - Output:
[2025-04-20T20:43:10.639+0000] {subprocess.py:93} INFO - 
[2025-04-20T20:43:10.639+0000] {subprocess.py:93} INFO - WARNING: apt does not have a stable CLI interface. Use with caution in scripts.
[2025-04-20T20:43:10.640+0000] {subprocess.py:93} INFO - 
[2025-04-20T20:43:10.697+0000] {subprocess.py:93} INFO - Reading package lists...
[2025-04-20T20:43:10.701+0000] {subprocess.py:93} INFO - E: List directory /var/lib/apt/lists/partial is missing. - Acquire (13: Permission denied)
[2025-04-20T20:43:10.704+0000] {subprocess.py:97} INFO - Command exited with return code 100
[2025-04-20T20:43:10.705+0000] {taskinstance.py:441} INFO - ::group::Post task execution logs
[2025-04-20T20:43:10.723+0000] {taskinstance.py:2905} ERROR - Task failed with exception
Traceback (most recent call last):
  File "/home/airflow/.local/lib/python3.12/site-packages/airflow/models/taskinstance.py", line 465, in _execute_task
    result = _execute_callable(context=context, **execute_callable_kwargs)
             ^^^^^^^^^^^^^^^^^^^^^^^^^^^^^^^^^^^^^^^^^^^^^^^^^^^^^^^^^^^^^
  File "/home/airflow/.local/lib/python3.12/site-packages/airflow/models/taskinstance.py", line 432, in _execute_callable
    return execute_callable(context=context, **execute_callable_kwargs)
           ^^^^^^^^^^^^^^^^^^^^^^^^^^^^^^^^^^^^^^^^^^^^^^^^^^^^^^^^^^^^
  File "/home/airflow/.local/lib/python3.12/site-packages/airflow/models/baseoperator.py", line 400, in wrapper
    return func(self, *args, **kwargs)
           ^^^^^^^^^^^^^^^^^^^^^^^^^^^
  File "/home/airflow/.local/lib/python3.12/site-packages/airflow/operators/bash.py", line 243, in execute
    raise AirflowException(
airflow.exceptions.AirflowException: Bash command failed. The command returned a non-zero exit code 100.
[2025-04-20T20:43:10.729+0000] {taskinstance.py:1206} INFO - Marking task as FAILED. dag_id=log_etl_dag, task_id=ingest_logs_to_minio, run_id=scheduled__2025-04-19T00:00:00+00:00, execution_date=20250419T000000, start_date=20250420T204310, end_date=20250420T204310
[2025-04-20T20:43:10.805+0000] {standard_task_runner.py:110} ERROR - Failed to execute job 47 for task ingest_logs_to_minio (Bash command failed. The command returned a non-zero exit code 100.; 218)
[2025-04-20T20:43:10.842+0000] {local_task_job_runner.py:240} INFO - Task exited with return code 1
[2025-04-20T20:43:10.897+0000] {taskinstance.py:3498} INFO - 0 downstream tasks scheduled from follow-on schedule check
[2025-04-20T20:43:10.901+0000] {local_task_job_runner.py:222} INFO - ::endgroup::
