[2025-04-20T20:22:13.051+0000] {local_task_job_runner.py:120} INFO - ::group::Pre task execution logs
[2025-04-20T20:22:13.075+0000] {taskinstance.py:2076} INFO - Dependencies all met for dep_context=non-requeueable deps ti=<TaskInstance: log_etl_dag.ingest_logs_to_minio scheduled__2025-04-19T00:00:00+00:00 [queued]>
[2025-04-20T20:22:13.081+0000] {taskinstance.py:2076} INFO - Dependencies all met for dep_context=requeueable deps ti=<TaskInstance: log_etl_dag.ingest_logs_to_minio scheduled__2025-04-19T00:00:00+00:00 [queued]>
[2025-04-20T20:22:13.081+0000] {taskinstance.py:2306} INFO - Starting attempt 1 of 2
[2025-04-20T20:22:13.091+0000] {taskinstance.py:2330} INFO - Executing <Task(BashOperator): ingest_logs_to_minio> on 2025-04-19 00:00:00+00:00
[2025-04-20T20:22:13.098+0000] {logging_mixin.py:188} WARNING - /home/***/.local/lib/python3.12/site-packages/***/task/task_runner/standard_task_runner.py:61 DeprecationWarning: This process (pid=217) is multi-threaded, use of fork() may lead to deadlocks in the child.
[2025-04-20T20:22:13.099+0000] {standard_task_runner.py:63} INFO - Started process 218 to run task
[2025-04-20T20:22:13.098+0000] {standard_task_runner.py:90} INFO - Running: ['***', 'tasks', 'run', 'log_etl_dag', 'ingest_logs_to_minio', 'scheduled__2025-04-19T00:00:00+00:00', '--job-id', '45', '--raw', '--subdir', 'DAGS_FOLDER/log_etl_dag.py', '--cfg-path', '/tmp/tmpcmq1lr40']
[2025-04-20T20:22:13.101+0000] {standard_task_runner.py:91} INFO - Job 45: Subtask ingest_logs_to_minio
[2025-04-20T20:22:13.111+0000] {logging_mixin.py:188} WARNING - /home/***/.local/lib/python3.12/site-packages/***/settings.py:195 DeprecationWarning: The sql_alchemy_conn option in [core] has been moved to the sql_alchemy_conn option in [database] - the old setting has been used, but please update your config.
[2025-04-20T20:22:13.136+0000] {task_command.py:426} INFO - Running <TaskInstance: log_etl_dag.ingest_logs_to_minio scheduled__2025-04-19T00:00:00+00:00 [running]> on host 2f6869e3257c
[2025-04-20T20:22:13.226+0000] {taskinstance.py:2648} INFO - Exporting env vars: AIRFLOW_CTX_DAG_OWNER='***' AIRFLOW_CTX_DAG_ID='log_etl_dag' AIRFLOW_CTX_TASK_ID='ingest_logs_to_minio' AIRFLOW_CTX_EXECUTION_DATE='2025-04-19T00:00:00+00:00' AIRFLOW_CTX_TRY_NUMBER='1' AIRFLOW_CTX_DAG_RUN_ID='scheduled__2025-04-19T00:00:00+00:00'
[2025-04-20T20:22:13.227+0000] {taskinstance.py:430} INFO - ::endgroup::
[2025-04-20T20:22:13.257+0000] {subprocess.py:63} INFO - Tmp dir root location: /tmp
[2025-04-20T20:22:13.258+0000] {subprocess.py:75} INFO - Running command: ['/usr/bin/bash', '-c', '\n        apt update && apt install -y mc &&         mc alias set localminio http://minio:9000 minioadmin minioadmin &&         mc cp /opt/***/data/access_log.txt localminio/log-bucket/raw-logs/\n        ']
[2025-04-20T20:22:13.265+0000] {subprocess.py:86} INFO - Output:
[2025-04-20T20:22:13.355+0000] {subprocess.py:93} INFO - 
[2025-04-20T20:22:13.356+0000] {subprocess.py:93} INFO - WARNING: apt does not have a stable CLI interface. Use with caution in scripts.
[2025-04-20T20:22:13.356+0000] {subprocess.py:93} INFO - 
[2025-04-20T20:22:13.390+0000] {subprocess.py:93} INFO - Reading package lists...
[2025-04-20T20:22:13.392+0000] {subprocess.py:93} INFO - E: List directory /var/lib/apt/lists/partial is missing. - Acquire (13: Permission denied)
[2025-04-20T20:22:13.395+0000] {subprocess.py:97} INFO - Command exited with return code 100
[2025-04-20T20:22:13.395+0000] {taskinstance.py:441} INFO - ::group::Post task execution logs
[2025-04-20T20:22:13.404+0000] {taskinstance.py:2905} ERROR - Task failed with exception
Traceback (most recent call last):
  File "/home/airflow/.local/lib/python3.12/site-packages/airflow/models/taskinstance.py", line 465, in _execute_task
    result = _execute_callable(context=context, **execute_callable_kwargs)
             ^^^^^^^^^^^^^^^^^^^^^^^^^^^^^^^^^^^^^^^^^^^^^^^^^^^^^^^^^^^^^
  File "/home/airflow/.local/lib/python3.12/site-packages/airflow/models/taskinstance.py", line 432, in _execute_callable
    return execute_callable(context=context, **execute_callable_kwargs)
           ^^^^^^^^^^^^^^^^^^^^^^^^^^^^^^^^^^^^^^^^^^^^^^^^^^^^^^^^^^^^
  File "/home/airflow/.local/lib/python3.12/site-packages/airflow/models/baseoperator.py", line 400, in wrapper
    return func(self, *args, **kwargs)
           ^^^^^^^^^^^^^^^^^^^^^^^^^^^
  File "/home/airflow/.local/lib/python3.12/site-packages/airflow/operators/bash.py", line 243, in execute
    raise AirflowException(
airflow.exceptions.AirflowException: Bash command failed. The command returned a non-zero exit code 100.
[2025-04-20T20:22:13.408+0000] {taskinstance.py:1206} INFO - Marking task as UP_FOR_RETRY. dag_id=log_etl_dag, task_id=ingest_logs_to_minio, run_id=scheduled__2025-04-19T00:00:00+00:00, execution_date=20250419T000000, start_date=20250420T202213, end_date=20250420T202213
[2025-04-20T20:22:13.418+0000] {standard_task_runner.py:110} ERROR - Failed to execute job 45 for task ingest_logs_to_minio (Bash command failed. The command returned a non-zero exit code 100.; 218)
[2025-04-20T20:22:13.433+0000] {local_task_job_runner.py:240} INFO - Task exited with return code 1
[2025-04-20T20:22:13.452+0000] {taskinstance.py:3498} INFO - 0 downstream tasks scheduled from follow-on schedule check
[2025-04-20T20:22:13.453+0000] {local_task_job_runner.py:222} INFO - ::endgroup::
