[2025-04-16T22:13:04.662+0000] {local_task_job_runner.py:120} INFO - ::group::Pre task execution logs
[2025-04-16T22:13:04.684+0000] {taskinstance.py:2076} INFO - Dependencies all met for dep_context=non-requeueable deps ti=<TaskInstance: log_etl_dag.spark_analytics manual__2025-04-16T22:13:04.458580+00:00 [queued]>
[2025-04-16T22:13:04.690+0000] {taskinstance.py:2076} INFO - Dependencies all met for dep_context=requeueable deps ti=<TaskInstance: log_etl_dag.spark_analytics manual__2025-04-16T22:13:04.458580+00:00 [queued]>
[2025-04-16T22:13:04.690+0000] {taskinstance.py:2306} INFO - Starting attempt 1 of 1
[2025-04-16T22:13:04.700+0000] {taskinstance.py:2330} INFO - Executing <Task(SparkSubmitOperator): spark_analytics> on 2025-04-16 22:13:04.458580+00:00
[2025-04-16T22:13:04.707+0000] {logging_mixin.py:188} WARNING - /home/***/.local/lib/python3.12/site-packages/***/task/task_runner/standard_task_runner.py:61 DeprecationWarning: This process (pid=949) is multi-threaded, use of fork() may lead to deadlocks in the child.
[2025-04-16T22:13:04.708+0000] {standard_task_runner.py:63} INFO - Started process 950 to run task
[2025-04-16T22:13:04.707+0000] {standard_task_runner.py:90} INFO - Running: ['***', 'tasks', 'run', 'log_etl_dag', 'spark_analytics', 'manual__2025-04-16T22:13:04.458580+00:00', '--job-id', '28', '--raw', '--subdir', 'DAGS_FOLDER/log_etl_dag.py', '--cfg-path', '/tmp/tmpq3a752lj']
[2025-04-16T22:13:04.709+0000] {standard_task_runner.py:91} INFO - Job 28: Subtask spark_analytics
[2025-04-16T22:13:04.719+0000] {logging_mixin.py:188} WARNING - /home/***/.local/lib/python3.12/site-packages/***/settings.py:195 DeprecationWarning: The sql_alchemy_conn option in [core] has been moved to the sql_alchemy_conn option in [database] - the old setting has been used, but please update your config.
[2025-04-16T22:13:04.743+0000] {task_command.py:426} INFO - Running <TaskInstance: log_etl_dag.spark_analytics manual__2025-04-16T22:13:04.458580+00:00 [running]> on host b029bdb81cc4
[2025-04-16T22:13:04.806+0000] {taskinstance.py:2648} INFO - Exporting env vars: AIRFLOW_CTX_DAG_OWNER='***' AIRFLOW_CTX_DAG_ID='log_etl_dag' AIRFLOW_CTX_TASK_ID='spark_analytics' AIRFLOW_CTX_EXECUTION_DATE='2025-04-16T22:13:04.458580+00:00' AIRFLOW_CTX_TRY_NUMBER='1' AIRFLOW_CTX_DAG_RUN_ID='manual__2025-04-16T22:13:04.458580+00:00'
[2025-04-16T22:13:04.807+0000] {taskinstance.py:430} INFO - ::endgroup::
[2025-04-16T22:13:04.831+0000] {base.py:84} INFO - Using connection ID 'spark_default' for task execution.
[2025-04-16T22:13:04.832+0000] {spark_submit.py:474} INFO - Spark-Submit cmd: spark-submit --master spark://spark-master:8080 --conf spark.hadoop.fs.s3a.endpoint=http://minio:9000 --conf spark.hadoop.fs.s3a.access.key=minioadmin --conf spark.hadoop.fs.s3a.secret.key=****** --conf spark.hadoop.fs.s3a.path.style.access=true --name arrow-spark --verbose --deploy-mode client /opt/bitnami/spark/work/log_analytics.py
[2025-04-16T22:13:04.916+0000] {spark_submit.py:645} INFO - /home/***/.local/lib/python3.12/site-packages/pyspark/bin/load-spark-env.sh: line 68: ps: command not found
[2025-04-16T22:13:04.918+0000] {spark_submit.py:645} INFO - JAVA_HOME is not set
[2025-04-16T22:13:04.919+0000] {taskinstance.py:441} INFO - ::group::Post task execution logs
[2025-04-16T22:13:04.931+0000] {taskinstance.py:2905} ERROR - Task failed with exception
Traceback (most recent call last):
  File "/home/airflow/.local/lib/python3.12/site-packages/airflow/models/taskinstance.py", line 465, in _execute_task
    result = _execute_callable(context=context, **execute_callable_kwargs)
             ^^^^^^^^^^^^^^^^^^^^^^^^^^^^^^^^^^^^^^^^^^^^^^^^^^^^^^^^^^^^^
  File "/home/airflow/.local/lib/python3.12/site-packages/airflow/models/taskinstance.py", line 432, in _execute_callable
    return execute_callable(context=context, **execute_callable_kwargs)
           ^^^^^^^^^^^^^^^^^^^^^^^^^^^^^^^^^^^^^^^^^^^^^^^^^^^^^^^^^^^^
  File "/home/airflow/.local/lib/python3.12/site-packages/airflow/models/baseoperator.py", line 400, in wrapper
    return func(self, *args, **kwargs)
           ^^^^^^^^^^^^^^^^^^^^^^^^^^^
  File "/home/airflow/.local/lib/python3.12/site-packages/airflow/providers/apache/spark/operators/spark_submit.py", line 197, in execute
    self._hook.submit(self.application)
  File "/home/airflow/.local/lib/python3.12/site-packages/airflow/providers/apache/spark/hooks/spark_submit.py", line 567, in submit
    raise AirflowException(
airflow.exceptions.AirflowException: Cannot execute: spark-submit --master spark://spark-master:8080 --conf spark.hadoop.fs.s3a.endpoint=http://minio:9000 --conf spark.hadoop.fs.s3a.access.key=minioadmin --conf spark.hadoop.fs.s3a.secret.key=****** --conf spark.hadoop.fs.s3a.path.style.access=true --name arrow-spark --verbose --deploy-mode client /opt/bitnami/spark/work/log_analytics.py. Error code is: 1.
[2025-04-16T22:13:04.936+0000] {taskinstance.py:1206} INFO - Marking task as FAILED. dag_id=log_etl_dag, task_id=spark_analytics, run_id=manual__2025-04-16T22:13:04.458580+00:00, execution_date=20250416T221304, start_date=20250416T221304, end_date=20250416T221304
[2025-04-16T22:13:04.948+0000] {standard_task_runner.py:110} ERROR - Failed to execute job 28 for task spark_analytics (Cannot execute: spark-submit --master spark://spark-master:8080 --conf spark.hadoop.fs.s3a.endpoint=http://minio:9000 --conf spark.hadoop.fs.s3a.access.key=minioadmin --conf spark.hadoop.fs.s3a.secret.key=****** --conf spark.hadoop.fs.s3a.path.style.access=true --name arrow-spark --verbose --deploy-mode client /opt/bitnami/spark/work/log_analytics.py. Error code is: 1.; 950)
[2025-04-16T22:13:04.964+0000] {local_task_job_runner.py:240} INFO - Task exited with return code 1
[2025-04-16T22:13:04.988+0000] {taskinstance.py:3498} INFO - 0 downstream tasks scheduled from follow-on schedule check
[2025-04-16T22:13:05.025+0000] {local_task_job_runner.py:222} INFO - ::endgroup::
