[2025-04-16T22:12:52.672+0000] {local_task_job_runner.py:120} INFO - ::group::Pre task execution logs
[2025-04-16T22:12:52.695+0000] {taskinstance.py:2076} INFO - Dependencies all met for dep_context=non-requeueable deps ti=<TaskInstance: log_etl_dag.spark_analytics manual__2025-04-16T22:12:51.456673+00:00 [queued]>
[2025-04-16T22:12:52.701+0000] {taskinstance.py:2076} INFO - Dependencies all met for dep_context=requeueable deps ti=<TaskInstance: log_etl_dag.spark_analytics manual__2025-04-16T22:12:51.456673+00:00 [queued]>
[2025-04-16T22:12:52.702+0000] {taskinstance.py:2306} INFO - Starting attempt 1 of 1
[2025-04-16T22:12:52.712+0000] {taskinstance.py:2330} INFO - Executing <Task(SparkSubmitOperator): spark_analytics> on 2025-04-16 22:12:51.456673+00:00
[2025-04-16T22:12:52.719+0000] {logging_mixin.py:188} WARNING - /home/***/.local/lib/python3.12/site-packages/***/task/task_runner/standard_task_runner.py:61 DeprecationWarning: This process (pid=934) is multi-threaded, use of fork() may lead to deadlocks in the child.
[2025-04-16T22:12:52.721+0000] {standard_task_runner.py:63} INFO - Started process 935 to run task
[2025-04-16T22:12:52.719+0000] {standard_task_runner.py:90} INFO - Running: ['***', 'tasks', 'run', 'log_etl_dag', 'spark_analytics', 'manual__2025-04-16T22:12:51.456673+00:00', '--job-id', '27', '--raw', '--subdir', 'DAGS_FOLDER/log_etl_dag.py', '--cfg-path', '/tmp/tmpf8yvjizg']
[2025-04-16T22:12:52.722+0000] {standard_task_runner.py:91} INFO - Job 27: Subtask spark_analytics
[2025-04-16T22:12:52.737+0000] {logging_mixin.py:188} WARNING - /home/***/.local/lib/python3.12/site-packages/***/settings.py:195 DeprecationWarning: The sql_alchemy_conn option in [core] has been moved to the sql_alchemy_conn option in [database] - the old setting has been used, but please update your config.
[2025-04-16T22:12:52.772+0000] {task_command.py:426} INFO - Running <TaskInstance: log_etl_dag.spark_analytics manual__2025-04-16T22:12:51.456673+00:00 [running]> on host b029bdb81cc4
[2025-04-16T22:12:52.839+0000] {taskinstance.py:2648} INFO - Exporting env vars: AIRFLOW_CTX_DAG_OWNER='***' AIRFLOW_CTX_DAG_ID='log_etl_dag' AIRFLOW_CTX_TASK_ID='spark_analytics' AIRFLOW_CTX_EXECUTION_DATE='2025-04-16T22:12:51.456673+00:00' AIRFLOW_CTX_TRY_NUMBER='1' AIRFLOW_CTX_DAG_RUN_ID='manual__2025-04-16T22:12:51.456673+00:00'
[2025-04-16T22:12:52.840+0000] {taskinstance.py:430} INFO - ::endgroup::
[2025-04-16T22:12:52.877+0000] {base.py:84} INFO - Using connection ID 'spark_default' for task execution.
[2025-04-16T22:12:52.878+0000] {spark_submit.py:474} INFO - Spark-Submit cmd: spark-submit --master spark://spark-master:8080 --conf spark.hadoop.fs.s3a.endpoint=http://minio:9000 --conf spark.hadoop.fs.s3a.access.key=minioadmin --conf spark.hadoop.fs.s3a.secret.key=****** --conf spark.hadoop.fs.s3a.path.style.access=true --name arrow-spark --verbose --deploy-mode client /opt/bitnami/spark/work/log_analytics.py
[2025-04-16T22:12:53.006+0000] {spark_submit.py:645} INFO - /home/***/.local/lib/python3.12/site-packages/pyspark/bin/load-spark-env.sh: line 68: ps: command not found
[2025-04-16T22:12:53.006+0000] {spark_submit.py:645} INFO - JAVA_HOME is not set
[2025-04-16T22:12:53.007+0000] {taskinstance.py:441} INFO - ::group::Post task execution logs
[2025-04-16T22:12:53.015+0000] {taskinstance.py:2905} ERROR - Task failed with exception
Traceback (most recent call last):
  File "/home/airflow/.local/lib/python3.12/site-packages/airflow/models/taskinstance.py", line 465, in _execute_task
    result = _execute_callable(context=context, **execute_callable_kwargs)
             ^^^^^^^^^^^^^^^^^^^^^^^^^^^^^^^^^^^^^^^^^^^^^^^^^^^^^^^^^^^^^
  File "/home/airflow/.local/lib/python3.12/site-packages/airflow/models/taskinstance.py", line 432, in _execute_callable
    return execute_callable(context=context, **execute_callable_kwargs)
           ^^^^^^^^^^^^^^^^^^^^^^^^^^^^^^^^^^^^^^^^^^^^^^^^^^^^^^^^^^^^
  File "/home/airflow/.local/lib/python3.12/site-packages/airflow/models/baseoperator.py", line 400, in wrapper
    return func(self, *args, **kwargs)
           ^^^^^^^^^^^^^^^^^^^^^^^^^^^
  File "/home/airflow/.local/lib/python3.12/site-packages/airflow/providers/apache/spark/operators/spark_submit.py", line 197, in execute
    self._hook.submit(self.application)
  File "/home/airflow/.local/lib/python3.12/site-packages/airflow/providers/apache/spark/hooks/spark_submit.py", line 567, in submit
    raise AirflowException(
airflow.exceptions.AirflowException: Cannot execute: spark-submit --master spark://spark-master:8080 --conf spark.hadoop.fs.s3a.endpoint=http://minio:9000 --conf spark.hadoop.fs.s3a.access.key=minioadmin --conf spark.hadoop.fs.s3a.secret.key=****** --conf spark.hadoop.fs.s3a.path.style.access=true --name arrow-spark --verbose --deploy-mode client /opt/bitnami/spark/work/log_analytics.py. Error code is: 1.
[2025-04-16T22:12:53.018+0000] {taskinstance.py:1206} INFO - Marking task as FAILED. dag_id=log_etl_dag, task_id=spark_analytics, run_id=manual__2025-04-16T22:12:51.456673+00:00, execution_date=20250416T221251, start_date=20250416T221252, end_date=20250416T221253
[2025-04-16T22:12:53.026+0000] {standard_task_runner.py:110} ERROR - Failed to execute job 27 for task spark_analytics (Cannot execute: spark-submit --master spark://spark-master:8080 --conf spark.hadoop.fs.s3a.endpoint=http://minio:9000 --conf spark.hadoop.fs.s3a.access.key=minioadmin --conf spark.hadoop.fs.s3a.secret.key=****** --conf spark.hadoop.fs.s3a.path.style.access=true --name arrow-spark --verbose --deploy-mode client /opt/bitnami/spark/work/log_analytics.py. Error code is: 1.; 935)
[2025-04-16T22:12:53.058+0000] {local_task_job_runner.py:240} INFO - Task exited with return code 1
[2025-04-16T22:12:53.072+0000] {taskinstance.py:3498} INFO - 0 downstream tasks scheduled from follow-on schedule check
[2025-04-16T22:12:53.073+0000] {local_task_job_runner.py:222} INFO - ::endgroup::
