[2025-04-19T18:43:23.371+0000] {local_task_job_runner.py:120} INFO - ::group::Pre task execution logs
[2025-04-19T18:43:23.428+0000] {taskinstance.py:2076} INFO - Dependencies all met for dep_context=non-requeueable deps ti=<TaskInstance: log_etl_dag.spark_analytics manual__2025-04-19T18:43:22.261888+00:00 [queued]>
[2025-04-19T18:43:23.438+0000] {taskinstance.py:2076} INFO - Dependencies all met for dep_context=requeueable deps ti=<TaskInstance: log_etl_dag.spark_analytics manual__2025-04-19T18:43:22.261888+00:00 [queued]>
[2025-04-19T18:43:23.438+0000] {taskinstance.py:2306} INFO - Starting attempt 1 of 1
[2025-04-19T18:43:23.452+0000] {taskinstance.py:2330} INFO - Executing <Task(SparkSubmitOperator): spark_analytics> on 2025-04-19 18:43:22.261888+00:00
[2025-04-19T18:43:23.464+0000] {logging_mixin.py:188} WARNING - /home/***/.local/lib/python3.12/site-packages/***/task/task_runner/standard_task_runner.py:61 DeprecationWarning: This process (pid=237) is multi-threaded, use of fork() may lead to deadlocks in the child.
[2025-04-19T18:43:23.465+0000] {standard_task_runner.py:63} INFO - Started process 238 to run task
[2025-04-19T18:43:23.468+0000] {standard_task_runner.py:90} INFO - Running: ['***', 'tasks', 'run', 'log_etl_dag', 'spark_analytics', 'manual__2025-04-19T18:43:22.261888+00:00', '--job-id', '34', '--raw', '--subdir', 'DAGS_FOLDER/log_etl_dag.py', '--cfg-path', '/tmp/tmpxn5c6u0g']
[2025-04-19T18:43:23.470+0000] {standard_task_runner.py:91} INFO - Job 34: Subtask spark_analytics
[2025-04-19T18:43:23.484+0000] {logging_mixin.py:188} WARNING - /home/***/.local/lib/python3.12/site-packages/***/settings.py:195 DeprecationWarning: The sql_alchemy_conn option in [core] has been moved to the sql_alchemy_conn option in [database] - the old setting has been used, but please update your config.
[2025-04-19T18:43:23.541+0000] {task_command.py:426} INFO - Running <TaskInstance: log_etl_dag.spark_analytics manual__2025-04-19T18:43:22.261888+00:00 [running]> on host c78215a515b5
[2025-04-19T18:43:23.791+0000] {taskinstance.py:2648} INFO - Exporting env vars: AIRFLOW_CTX_DAG_OWNER='***' AIRFLOW_CTX_DAG_ID='log_etl_dag' AIRFLOW_CTX_TASK_ID='spark_analytics' AIRFLOW_CTX_EXECUTION_DATE='2025-04-19T18:43:22.261888+00:00' AIRFLOW_CTX_TRY_NUMBER='1' AIRFLOW_CTX_DAG_RUN_ID='manual__2025-04-19T18:43:22.261888+00:00'
[2025-04-19T18:43:23.791+0000] {taskinstance.py:430} INFO - ::endgroup::
[2025-04-19T18:43:23.846+0000] {base.py:84} INFO - Using connection ID 'spark_default' for task execution.
[2025-04-19T18:43:23.848+0000] {spark_submit.py:474} INFO - Spark-Submit cmd: spark-submit --master spark://spark-master:7077 --conf spark.hadoop.fs.s3a.endpoint=http://minio:9000 --conf spark.hadoop.fs.s3a.access.key=minioadmin --conf spark.hadoop.fs.s3a.secret.key=****** --conf spark.hadoop.fs.s3a.path.style.access=true --name arrow-spark --verbose --deploy-mode client /opt/bitnami/spark/work/log_analytics.py
[2025-04-19T18:43:23.950+0000] {spark_submit.py:644} INFO - /home/***/.local/lib/python3.12/site-packages/pyspark/bin/load-spark-env.sh: line 68: ps: command not found
[2025-04-19T18:43:23.951+0000] {spark_submit.py:644} INFO - JAVA_HOME is not set
[2025-04-19T18:43:23.952+0000] {taskinstance.py:441} INFO - ::group::Post task execution logs
[2025-04-19T18:43:23.960+0000] {taskinstance.py:2905} ERROR - Task failed with exception
Traceback (most recent call last):
  File "/home/airflow/.local/lib/python3.12/site-packages/airflow/models/taskinstance.py", line 465, in _execute_task
    result = _execute_callable(context=context, **execute_callable_kwargs)
             ^^^^^^^^^^^^^^^^^^^^^^^^^^^^^^^^^^^^^^^^^^^^^^^^^^^^^^^^^^^^^
  File "/home/airflow/.local/lib/python3.12/site-packages/airflow/models/taskinstance.py", line 432, in _execute_callable
    return execute_callable(context=context, **execute_callable_kwargs)
           ^^^^^^^^^^^^^^^^^^^^^^^^^^^^^^^^^^^^^^^^^^^^^^^^^^^^^^^^^^^^
  File "/home/airflow/.local/lib/python3.12/site-packages/airflow/models/baseoperator.py", line 400, in wrapper
    return func(self, *args, **kwargs)
           ^^^^^^^^^^^^^^^^^^^^^^^^^^^
  File "/home/airflow/.local/lib/python3.12/site-packages/airflow/providers/apache/spark/operators/spark_submit.py", line 197, in execute
    self._hook.submit(self.application)
  File "/home/airflow/.local/lib/python3.12/site-packages/airflow/providers/apache/spark/hooks/spark_submit.py", line 566, in submit
    raise AirflowException(
airflow.exceptions.AirflowException: Cannot execute: spark-submit --master spark://spark-master:7077 --conf spark.hadoop.fs.s3a.endpoint=http://minio:9000 --conf spark.hadoop.fs.s3a.access.key=minioadmin --conf spark.hadoop.fs.s3a.secret.key=****** --conf spark.hadoop.fs.s3a.path.style.access=true --name arrow-spark --verbose --deploy-mode client /opt/bitnami/spark/work/log_analytics.py. Error code is: 1.
[2025-04-19T18:43:23.967+0000] {taskinstance.py:1206} INFO - Marking task as FAILED. dag_id=log_etl_dag, task_id=spark_analytics, run_id=manual__2025-04-19T18:43:22.261888+00:00, execution_date=20250419T184322, start_date=20250419T184323, end_date=20250419T184323
[2025-04-19T18:43:23.979+0000] {standard_task_runner.py:110} ERROR - Failed to execute job 34 for task spark_analytics (Cannot execute: spark-submit --master spark://spark-master:7077 --conf spark.hadoop.fs.s3a.endpoint=http://minio:9000 --conf spark.hadoop.fs.s3a.access.key=minioadmin --conf spark.hadoop.fs.s3a.secret.key=****** --conf spark.hadoop.fs.s3a.path.style.access=true --name arrow-spark --verbose --deploy-mode client /opt/bitnami/spark/work/log_analytics.py. Error code is: 1.; 238)
[2025-04-19T18:43:24.014+0000] {local_task_job_runner.py:240} INFO - Task exited with return code 1
[2025-04-19T18:43:24.039+0000] {taskinstance.py:3498} INFO - 0 downstream tasks scheduled from follow-on schedule check
[2025-04-19T18:43:24.040+0000] {local_task_job_runner.py:222} INFO - ::endgroup::
